Workbook

Sheet design_ranges
A1: variable | B1: min | C1: max | D1: unit | E1: description
A2: t2_days | B2: 2 | C2: 7 | D2: days | E2: Cold-drying duration before roasting
A3: T3_C | B3: 75 | C3: 85 | D3: C | E3: Phase 3 air temperature
A4: T4_C | B4: 80 | C4: 100 | D4: C | E4: Phase 4 air temperature
A5: T5_C | B5: 130 | C5: 170 | D5: C | E5: Phase 5 air temperature
A6: T6_8_C | B6: 220 | C6: 260 | D6: C | E6: Phases 6-8 air temperature range
A7: t3_min | B7: 15 | C7: 45 | D7: min | E7: Phase 3 duration
A8: t4_min | B8: 30 | C8: 90 | D8: min | E8: Phase 4 duration
A9: t5_min | B9: 12.5 | C9: 37.5 | D9: min | E9: Phase 5 duration
A10: t6_min | B10: 12.5 | C10: 37.5 | D10: min | E10: Phase 6 duration
A11: t7_min | B11: 2.5 | C11: 7.5 | D11: min | E11: Phase 7 duration
A12: t8_min | B12: 2.5 | C12: 7.5 | D12: min | E12: Phase 8 duration
A13: RH3 | B13: 1 | C13: 1 | D13: - | E13: Phase 3 relative humidity
... A15: RH5 | B15: 0.3 | C15: 0.7 | D15: - | E15: Phase 5 relative humidity

Sheet candidates
A1: idx | B1: t2_days | C1: T3_C | D1: T4_C | E1: T5_C | F1: T6_C | G1: T7_C | H1: T8_C | I1: t3_min | J1: t4_min | K1: t5_min | L1: t6_min | M1: t7_min | N1: t8_min | O1: RH3 | P1: RH4 | Q1: RH5 | R1: C_gross | S1: J_gross | T1: R_raw | U1: C_norm | V1: J_norm | W1: R_norm | X1: Phi | Y1: PC1 | Z1: PC2 | AA1: is_pareto | AB1: is_mario | AC1: is_exp_test | AD1: cluster_id | AE1: is_chef | AF1: cluster_pca | AG1: Balancedindex
A2: 0 | B2: 6.2846211 | C2: 77.288944 | D2: 81.201351 | E2: 149.33765 | F2: 236.02145 | G2: 249.62223 | H2: 257.25869 | I2: 44.798133 | J2: 83.466545 | K2: 29.700485 | L2: 34.989598 | M2: 2.8534185 | N2: 3.6972213 | O2: 1 | P2: 0.30825388 | Q2: 0.36594109 | R2: 0.001469715 | S2: 0.93681197 | T2: 785.94646 | U2: 0.76352682 | V2: 0.051383618 | W2: 0.85995216 | X2: 0.55828753 | Y2: -3.330282 | Z2: 0.7136417 | AA2: =FALSE() -> FALSE | AB2: =FALSE() -> FALSE | AC2: =FALSE() -> FALSE | AD2: -1 | AE2: =FALSE() -> FALSE | AG2: =1/3*(U2+V2+W2) -> 0.55828753
A3: 1 | B3: 6.3368559 | C3: 84.064342 | D3: 88.957824 | E3: 150.91021 | F3: 256.4904 | G3: 252.93225 | H3: 254.54453 | I3: 42.466599 | J3: 51.970696 | K3: 14.856113 | L3: 35.309869 | M3: 4.1046778 | N3: 5.4781176 | O3: 1 | P3: 0.34652111 | Q3: 0.31405352 | R3: 0.0009112226 | S3: 0.94628956 | T3: 861.07118 | U3: 0.41382483 | V3: 0.37590708 | W3: 0.72335179 | X3: 0.50436123 | Y3: -0.52724912 | Z3: -0.29200749 | AA3: =FALSE() -> FALSE | AB3: =FALSE() -> FALSE | AC3: =FALSE() -> FALSE | AD3: -1 | AE3: =FALSE() -> FALSE | AG3: =1/3*(U3+V3+W3) -> 0.50436123
A4: 2 | B4: 3.3135754 | C4: 75.844661 | D4: 86.433787 | E4: 164.35034 | F4: 226.33519 | G4: 230.62761 | H4: 232.63272 | I4: 22.440623 | J4: 37.0301 | K4: 13.056052 | L4: 21.262902 | M4: 5.9322249 | N4: 5.0411152 | O4: 1 | P4: 0.34187954 | Q4: 0.39369906 | R4: 0.00048662983 | S4: 0.95890098 | T4: 1161.9659 | U4: 0.14796455 | V4: 0.80773608 | W4: 0.17623052 | X4: 0.37731038 | Y4: 3.7744869 | Z4: 0.67672798 | AA4: =FALSE() -> FALSE | AB4: =FALSE() -> FALSE | AC4: =FALSE() -> FALSE | AD4: -1 | AE4: =FALSE() -> FALSE | AG4: =1/3*(U4+V4+W4) -> 0.37731038
A5: 3 | B5: 3.9244336 | C5: 77.735804 | D5: 92.25763 | E5: 149.21327 | F5: 245.11162 | G5: 232.76957 | H5: 249.37243 | I5: 28.183832 | J5: 55.616473 | K5: 26.955797 | L5: 27.596326 | M5: 5.1014163 | N5: 6.1279701 | O5: 1 | P5: 0.44527009 | Q5: 0.63233648 | R5: 0.0010224963 | S5: 0.9477248 | T5: 934.17094 | U5: 0.48349924 | V5: 0.42505116 | W5: 0.59043345 | X5: 0.49966128 | Y5: -0.13209595 | Z5: 0.56387542 | AA5: =FALSE() -> FALSE | AB5: =FALSE() -> FALSE | AC5: =FALSE() -> FALSE | AD5: -1 | AE5: =FALSE() -> FALSE | AG5: =1/3*(U5+V5+W5) -> 0.49966128
A6: 4 | B6: 3.8829079 | C6: 78.935675 | D6: 91.69814 | E6: 169.98319 | F6: 254.30023 | G6: 225.58384 | H6: 244.14006 | I6: 18.517537 | J6: 73.18323 | K6: 22.356832 | L6: 16.276149 | M6: 4.2330362 | N6: 5.8454158 | O6: 1 | P6: 0.40751852 | Q6: 0.39543878 | R6: 0.00086501144 | S6: 0.94984367 | T6: 892.79554 | U6: 0.38488955 | V6: 0.49760378 | W6: 0.66566695 | X6: 0.51605342 | Y6: 0.2043174 | Z6: -0.14663502 | AA6: =FALSE() -> FALSE | AB6: =FALSE() -> FALSE | AC6: =FALSE() -> FALSE | AD6: -1 | AE6: =FALSE() -> FALSE | AG6: =1/3*(U6+V6+W6) -> 0.51605342
A7: 5 | B7: 3.2204002 | C7: 83.542502 | D7: 84.91943 | E7: 159.49843 | F7: 227.00617 | G7: 251.20487 | H7: 237.65101 | I7: 41.477518 | J7: 38.926304 | K7: 35.324326 | L7: 14.634374 | M7: 7.3242855 | N7: 4.1239693 | O7: 1 | P7: 0.41155825 | Q7: 0.5794428 | R7: 0.00083736993 | S7: 0.94964579 | T7: 929.50203 | U7: 0.36758172 | V7: 0.4908281 | W7: 0.59892299 | X7: 0.48577761 | Y7: 0.46390045 | Z7: 0.0081797218 | AA7: =FALSE() -> FALSE | AB7: =FALSE() -> FALSE | AC7: =FALSE() -> FALSE | AD7: -1 | AE7: =FALSE() -> FALSE | AG7: =1/3*(U7+V7+W7) -> 0.48577761
A8: 6 | B8: 4.2283171 | C8: 83.222633 | D8: 81.640867 | E8: 157.2537 | F8: 223.96744 | G8: 248.35495 | H8: 221.50299 | I8: 29.600339 | J8: 85.118836 | K8: 23.479927 | L8: 13.481928 | M8: 7.4545998 | N8: 4.6020333 | O8: 1 | P8: 0.56637283 | Q8: 0.63192639 | R8: 0.00085575556 | S8: 0.94453426 | T8: 785.06404 | U8: 0.37909395 | V8: 0.31580336 | W8: 0.86155668 | X8: 0.518818 | Y8: -1.0966378 | Z8: -1.003455 | AA8: =FALSE() -> FALSE | AB8: =FALSE() -> FALSE | AC8: =FALSE() -> FALSE | AD8: -1 | AE8: =FALSE() -> FALSE | AG8: =1/3*(U8+V8+W8) -> 0.518818
A9: 7 | B9: 6.926055 | C9: 81.811642 | D9: 97.284444 | E9: 157.68956 | F9: 227.16958 | G9: 246.38553 | H9: 255.15358 | I9: 30.141167 | J9: 56.041055 | K9: 33.991438 | L9: 18.150685 | M9: 6.4881308 | N9: 6.6954203 | O9: 1 | P9: 0.4152138 | Q9: 0.40477761 | R9: 0.001194768 | S9: 0.94681531 | T9: 907.3329 | U9: 0.59136781 | V9: 0.39390914 | W9: 0.63923345 | X9: 0.54150347 | Y9: -0.77032859 | Z9: 0.89290121 | AA9: =FALSE() -> FALSE | AB9: =FALSE() -> FALSE | AC9: =FALSE() -> FALSE | AD9: -1 | AE9: =FALSE() -> FALSE | AG9: =1/3*(U9+V9+W9) -> 0.54150347
A10: 8 | B10: 2.7061142 | C10: 80.752073 | D10: 91.804354 | E10: 157.95312 | F10: 228.09321 | G10: 252.27436 | H10: 221.8283 | I10: 22.249126 | J10: 66.550318 | K10: 27.49599 | L10: 13.893479 | M10: 5.2017257 | N10: 5.7904882 | O10: 1 | P10: 0.67263017 | Q10: 0.30137732 | R10: 0.00062703996 | S10: 0.94990004 | T10: 896.90431 | U10: 0.23588286 | V10: 0.49953387 | W10: 0.6581959 | X10: 0.46453755 | Y10: 0.73444872 | Z10: -0.84556536 | AA10: =FALSE() -> FALSE | AB10: =FALSE() -> FALSE | AC10: =FALSE() -> FALSE | AD10: -1 | AE10: =FALSE() -> FALSE | AG10: =1/3*(U10+V10+W10) -> 0.46453755
A11: 9 | B11: 2.7460874 | C11: 77.994106 | D11: 95.262162 | E11: 131.21363 | F11: 245.64178 | G11: 252.54605 | H11: 251.23613 | I11: 27.071376 | J11: 36.027983 | K11: 29.130465 | L11: 14.03287 | M11: 7.2153952 | N11: 5.4433308 | O11: 1 | P11: 0.46092095 | Q11: 0.38626753 | R11: 0.00050751734 | S11: 0.95529167 | T11: 1023.6131 | U11: 0.16104334 | V11: 0.6841492 | W11: 0.42779951 | X11: 0.42433069 | Y11: 2.4319296 | Z11: -0.25470438 | AA11: =FALSE() -> FALSE | AB11: =FALSE() -> FALSE | AC11: =FALSE() -> FALSE | AD11: -1 | AE11: =FALSE() -> FALSE | AG11: =1/3*(U11+V11+W11) -> 0.42433069
A12: 10 | B12: 2.0903733 | C12: 79.183772 | D12: 97.916819 | E12: 159.21108 | F12: 237.17955 | G12: 228.59432 | H12: 229.45116 | I12: 37.908341 | J12: 62.874837 | K12: 16.458808 | L12: 17.591777 | M12: 6.1054939 | N12: 3.7604614 | O12: 1 | P12: 0.303369 | Q12: 0.31659768 | R12: 0.0006238192 | S12: 0.94922959 | T12: 888.3378 | U12: 0.23386617 | V12: 0.47657674 | W12: 0.67377251 | X12: 0.46140514 | Y12: 0.60550676 | Z12: -0.9266107 | AA12: =FALSE() -> FALSE | AB12: =FALSE() -> FALSE | AC12: =FALSE() -> FALSE | AD12: -1 | AE12: =FALSE() -> FALSE | AG12: =1/3*(U12+V12+W12) -> 0.46140514
A13: 11 | B13: 2.696371 | C13: 76.287075 | D13: 95.614131 | E13: 149.28387 | F13: 241.13422 | G13: 249.74693 | H13: 235.43329 | I13: 34.252424 | J13: 36.547668 | K13: 12.907376 | L13: 23.747367 | M13: 6.9932204 | N13: 5.9901885 | O13: 1 | P13: 0.43133039 | Q13: 0.5312617 | R13: 0.0005157975 | S13: 0.95491779 | T13: 1059.6387 | U13: 0.16622799 | V13: 0.67134723 | W13: 0.36229365 | X13: 0.39995629 | Y13: 2.59041 | Z13: 0.0016230255 | AA13: =FALSE() -> FALSE | AB13: =FALSE() -> FALSE | AC13: =FALSE() -> FALSE | AD13: -1 | AE13: =FALSE() -> FALSE | AG13: =1/3*(U13+V13+W13) -> 0.39995629
... A29: 27 | B29: 6.8387685 | C29: 76.989458 | D29: 85.401276 | E29: 164.25903 | F29: 249.56086 | G29: 237.51444 | H29: 250.48456 | I29: 19.749265 | J29: 58.433931 | K29: 18.356982 | L29: 16.511096 | M29: 3.5281315 | N29: 4.7425025 | O29: 1 | P29: 0.54369964 | Q29: 0.42971096 | R29: 0.00063345424 | S29: 0.95407288 | T29: 1019.9365 | U29: 0.23989918 | V29: 0.64241654 | W29: 0.43448472 | X29: 0.43893348 | Y29: 1.995136 | Z29: 0.07973983 | AA29: =FALSE() -> FALSE | AB29: =FALSE() -> FALSE | AC29: =FALSE() -> FALSE | AD29: -1 | AE29: =FALSE() -> FALSE | AG29: =1/3*(U29+V29+W29) -> 0.43893348
A30: 28 | B30: 6.4669778 | C30: 84.025854 | D30: 94.352801 | E30: 142.39477 | F30: 245.57052 | G30: 237.27048 | H30: 238.61842 | I30: 18.520511 | J30: 36.402973 | K30: 25.780782 | L30: 23.892825 | M30: 3.1279117 | N30: 3.3569109 | O30: 1 | P30: 0.43144733 | Q30: 0.31120952 | R30: 0.00064365513 | S30: 0.95677743 | T30: 1034.4965 | U30: 0.24628651 | V30: 0.73502345 | W30: 0.40801007 | X30: 0.46310667 | Y30: -0.42329995 | Z30: 0.01559738 | AA30: =TRUE() -> TRUE | AB30: =FALSE() -> FALSE | AC30: =FALSE() -> FALSE | AD30: 1 | AE30: =FALSE() -> FALSE | AF30: 1 | AG30: =1/3*(U30+V30+W30) -> 0.46310667
A31: 29 | B31: 4.7523926 | C31: 78.578475 | D31: 88.010647 | E31: 151.82163 | F31: 258.86457 | G31: 258.43158 | H31: 247.76859 | I31: 22.761196 | J31: 66.277527 | K31: 31.6211 | L31: 34.245122 | M31: 4.498785 | N31: 3.9422413 | O31: 1 | P31: 0.50834313 | Q31: 0.62656913 | R31: 0.0012887127 | S31: 0.94452089 | T31: 897.92161 | U31: 0.65019158 | V31: 0.31534555 | W31: 0.65634613 | X31: 0.54062776 | Y31: -1.3085117 | Z31: 1.0684644 | AA31: =FALSE() -> FALSE | AB31: =FALSE() -> FALSE | AC31: =FALSE() -> FALSE | AD31: -1 | AE31: =FALSE() -> FALSE | AG31: =1/3*(U31+V31+W31) -> 0.54062776
A32: 30 | B32: 4.3988167 | C32: 83.328728 | D32: 82.097147 | E32: 150.40861 | F32: 251.34963 | G32: 229.21143 | H32: 224.12246 | I32: 30.224119 | J32: 54.052577 | K32: 22.092147 | L32: 14.775352 | M32: 5.6800523 | N32: 5.6648318 | O32: 1 | P32: 0.34860126 | Q32: 0.42654389 | R32: 0.00066133506 | S32: 0.95163762 | T32: 931.87934 | U32: 0.25735686 | V32: 0.55903044 | W32: 0.59460031 | X32: 0.4703292 | Y32: 1.0930593 | Z32: -0.47145795 | AA32: =FALSE() -> FALSE | AB32: =FALSE() -> FALSE | AC32: =FALSE() -> FALSE | AD32: -1 | AE32: =FALSE() -> FALSE | AG32: =1/3*(U32+V32+W32) -> 0.4703292
A33: 31 | B33: 6.3816519 | C33: 83.579 | D33: 84.683603 | E33: 146.26296 | F33: 231.97905 | G33: 239.89952 | H33: 230.29541 | I33: 16.327605 | J33: 42.224878 | K33: 24.379221 | L33: 35.950289 | M33: 3.9852362 | N33: 5.5382991 | O33: 1 | P33: 0.56901339 | Q33: 0.31876599 | R33: 0.00089468369 | S33: 0.95235069 | T33: 1018.1641 | U33: 0.40346893 | V33: 0.58344683 | W33: 0.43770752 | X33: 0.47487443 | Y33: 1.2248101 | Z33: 0.82957837 | AA33: =FALSE() -> FALSE | AB33: =FALSE() -> FALSE | AC33: =FALSE() -> FALSE | AD33: -1 | AE33: =FALSE() -> FALSE | AG33: =1/3*(U33+V33+W33) -> 0.47487443
A34: 32 | B34: 4.1041866 | C34: 80.896679 | D34: 85.922805 | E34: 156.11908 | F34: 238.04337 | G34: 251.63732 | H34: 253.60716 | I34: 31.283641 | J34: 39.821744 | K34: 19.780489 | L34: 30.461125 | M34: 6.1399411 | N34: 3.1382293 | O34: 1 | P34: 0.52034328 | Q34: 0.45778802 | R34: 0.00070706063 | S34: 0.95213889 | T34: 1002.4085 | U34: 0.28598808 | V34: 0.57619448 | W34: 0.46635621 | X34: 0.44284626 | Y34: 1.4940361 | Z34: 0.14700291 | AA34: =FALSE() -> FALSE | AB34: =FALSE() -> FALSE | AC34: =FALSE() -> FALSE | AD34: -1 | AE34: =FALSE() -> FALSE | AG34: =1/3*(U34+V34+W34) -> 0.44284626
A35: 33 | B35: 3.2295277 | C35: 83.887524 | D35: 89.511194 | E35: 144.0364 | F35: 231.76405 | G35: 255.16389 | H35: 248.22698 | I35: 31.788673 | J35: 46.678073 | K35: 14.109736 | L35: 28.914365 | M35: 2.691823 | N35: 7.4823807 | O35: 1 | P35: 0.35298644 | Q35: 0.34413271 | R35: 0.00063212893 | S35: 0.9520458 | T35: 935.69038 | U35: 0.23906933 | V35: 0.57300718 | W35: 0.58767064 | X35: 0.46658238 | Y35: 1.2281082 | Z35: -0.52670126 | AA35: =FALSE() -> FALSE | AB35: =FALSE() -> FALSE | AC35: =FALSE() -> FALSE | AD35: -1 | AE35: =FALSE() -> FALSE | AG35: =1/3*(U35+V35+W35) -> 0.46658238
A36: 34 | B36: 2.194056 | C36: 81.283765 | D36: 99.780041 | E36: 137.72826 | F36: 258.11776 | G36: 240.22795 | H36: 252.22114 | I36: 39.645477 | J36: 35.930617 | K36: 19.487105 | L36: 33.582828 | M36: 2.6516413 | N36: 6.5470549 | O36: 1 | P36: 0.52898232 | Q36: 0.37621411 | R36: 0.00062680628 | S36: 0.95079323 | T36: 959.37238 | U36: 0.23573654 | V36: 0.53011775 | W36: 0.54460932 | X36: 0.4368212 | Y36: 1.2303447 | Z36: -0.41267519 | AA36: =FALSE() -> FALSE | AB36: =FALSE() -> FALSE | AC36: =FALSE() -> FALSE | AD36: -1 | AE36: =FALSE() -> FALSE | AG36: =1/3*(U36+V36+W36) -> 0.4368212
A37: 35 | B37: 3.3455758 | C37: 81.394291 | D37: 81.298059 | E37: 134.28811 | F37: 233.3567 | G37: 233.19816 | H37: 238.89878 | I37: 24.232623 | J37: 67.807843 | K37: 28.231205 | L37: 31.886322 | M37: 6.7576482 | N37: 6.3492558 | O37: 1 | P37: 0.63999826 | Q37: 0.46962946 | R37: 0.0009414464 | S37: 0.94438813 | T37: 869.36539 | U37: 0.43274957 | V37: 0.31079997 | W37: 0.70827031 | X37: 0.48393995 | Y37: -0.77442567 | Z37: -0.18532444 | AA37: =FALSE() -> FALSE | AB37: =FALSE() -> FALSE | AC37: =FALSE() -> FALSE | AD37: -1 | AE37: =FALSE() -> FALSE | AG37: =1/3*(U37+V37+W37) -> 0.48393995
A38: 36 | B38: 5.6968377 | C38: 82.542361 | D38: 92.337588 | E38: 162.88678 | F38: 236.6747 | G38: 228.78174 | H38: 220.96339 | I38: 33.093464 | J38: 52.513583 | K38: 23.136379 | L38: 24.027637 | M38: 4.2459332 | N38: 6.3478987 | O38: 1 | P38: 0.46015161 | Q38: 0.44439923 | R38: 0.00088285246 | S38: 0.94885591 | T38: 910.29026 | U38: 0.39606077 | V38: 0.4637817 | W38: 0.63385605 | X38: 0.4978995 | Y38: 0.15270026 | Z38: 0.0028152269 | AA38: =FALSE() -> FALSE | AB38: =FALSE() -> FALSE | AC38: =FALSE() -> FALSE | AD38: -1 | AE38: =FALSE() -> FALSE | AG38: =1/3*(U38+V38+W38) -> 0.4978995
A39: 37 | B39: 4.2354678 | C39: 78.527303 | D39: 80.791927 | E39: 135.60573 | F39: 224.68024 | G39: 229.51598 | H39: 239.0318 | I39: 22.015863 | J39: 58.81118 | K39: 29.960394 | L39: 37.445457 | M39: 3.5695376 | N39: 2.915431 | O39: 1 | P39: 0.3909921 | Q39: 0.33315894 | R39: 0.0010312346 | S39: 0.9465123 | T39: 938.92656 | U39: 0.48897076 | V39: 0.38353377 | W39: 0.58178625 | X39: 0.48476359 | Y39: -0.27096358 | Z39: 0.59616446 | AA39: =FALSE() -> FALSE | AB39: =FALSE() -> FALSE | AC39: =FALSE() -> FALSE | AD39: -1 | AE39: =FALSE() -> FALSE | AG39: =1/3*(U39+V39+W39) -> 0.48476359
A40: 38 | B40: 2.4073382 | C40: 81.910859 | D40: 94.76624 | E40: 148.95779 | F40: 231.20863 | G40: 231.97001 | H40: 253.48578 | I40: 27.469509 | J40: 56.221648 | K40: 35.843871 | L40: 37.479837 | M40: 5.2630802 | N40: 6.4098954 | O40: 1 | P40: 0.36136811 | Q40: 0.39619113 | R40: 0.001313415 | S40: 0.94388146 | T40: 902.16916 | U40: 0.66565905 | V40: 0.29345084 | W40: 0.64862275 | X40: 0.53591088 | Y40: -1.4130614 | Z40: 1.1584556 | AA40: =FALSE() -> FALSE | AB40: =FALSE() -> FALSE | AC40: =FALSE() -> FALSE | AD40: -1 | AE40: =FALSE() -> FALSE | AG40: =1/3*(U40+V40+W40) -> 0.53591088
A41: 39 | B41: 2.6843082 | C41: 78.872287 | D41: 94.646306 | E41: 137.06989 | F41: 224.35719 | G41: 236.79643 | H41: 252.65023 | I41: 22.614336 | J41: 37.794193 | K41: 13.749094 | L41: 36.02606 | M41: 4.2847112 | N41: 3.84964 | O41: 1 | P41: 0.49736794 | Q41: 0.43607211 | R41: 0.00059422151 | S41: 0.95545685 | T41: 1041.4462 | U41: 0.21533347 | V41: 0.68980514 | W41: 0.3953734 | X41: 0.433504 | Y41: 2.3808671 | Z41: 0.13218066 | AA41: =FALSE() -> FALSE | AB41: =FALSE() -> FALSE | AC41: =FALSE() -> FALSE | AD41: -1 | AE41: =FALSE() -> FALSE | AG41: =1/3*(U41+V41+W41) -> 0.433504
A42: 40 | B42: 6.5017754 | C42: 80.367018 | D42: 89.269594 | E42: 154.47781 | F42: 253.86256 | G42: 224.33782 | H42: 232.3027 | I42: 43.444872 | J42: 79.377554 | K42: 12.545324 | L42: 30.350485 | M42: 7.0939626 | N42: 7.2311882 | O42: 1 | P42: 0.37265123 | Q42: 0.48685359 | R42: 0.001122141 | S42: 0.94069402 | T42: 778.48806 | U42: 0.54589211 | V42: 0.18430926 | W42: 0.87351387 | X42: 0.53457175 | Y42: -2.169198 | Z42: -0.31510055 | AA42: =FALSE() -> FALSE | AB42: =FALSE() -> FALSE | AC42: =FALSE() -> FALSE | AD42: -1 | AE42: =FALSE() -> FALSE | AG42: =1/3*(U42+V42+W42) -> 0.53457175
... A53: 51 | B53: 3.180072 | C53: 84.968154 | D53: 81.277649 | E53: 142.5233 | F53: 254.94424 | G53: 222.37874 | H53: 253.65682 | I53: 28.494307 | J53: 54.083178 | K53: 23.890472 | L53: 18.918213 | M53: 4.6667623 | N53: 7.0919171 | O53: 1 | P53: 0.56808259 | Q53: 0.5539796 | R53: 0.00065768428 | S53: 0.95074696 | T53: 911.70857 | U53: 0.25507091 | V53: 0.52853314 | W53: 0.6312771 | X53: 0.47162705 | Y53: 0.86627758 | Z53: -0.63552828 | AA53: =FALSE() -> FALSE | AB53: =FALSE() -> FALSE | AC53: =FALSE() -> FALSE | AD53: -1 | AE53: =FALSE() -> FALSE | AG53: =1/3*(U53+V53+W53) -> 0.47162705
A54: 52 | B54: 5.0023393 | C54: 84.3358 | D54: 96.015325 | E54: 152.19579 | F54: 238.56374 | G54: 221.6748 | H54: 228.20699 | I54: 16.180893 | J54: 80.652038 | K54: 12.816228 | L54: 28.766984 | M54: 4.5447249 | N54: 2.692847 | O54: 1 | P54: 0.50629799 | Q54: 0.6542666 | R54: 0.00089989234 | S54: 0.94843248 | T54: 823.00363 | U54: 0.40673035 | V54: 0.44928294 | W54: 0.79257057 | X54: 0.54952795 | Y54: 0.059595462 | Z54: -0.12646726 | AA54: =TRUE() -> TRUE | AB54: =FALSE() -> FALSE | AC54: =FALSE() -> FALSE | AD54: 2 | AE54: =FALSE() -> FALSE | AF54: 2 | AG54: =1/3*(U54+V54+W54) -> 0.54952795
A55: 53 | B55: 4.9604033 | C55: 80.78836 | D55: 96.875537 | E55: 157.35552 | F55: 226.66262 | G55: 255.61393 | H55: 259.21474 | I55: 37.923611 | J55: 56.093026 | K55: 27.615834 | L55: 30.232781 | M55: 4.6595438 | N55: 4.7187752 | O55: 1 | P55: 0.65383222 | Q55: 0.51663225 | R55: 0.00097255418 | S55: 0.94494166 | T55: 885.04118 | U55: 0.45222782 | V55: 0.32975326 | W55: 0.67976681 | X55: 0.4872493 | Y55: -0.67446549 | Z55: 0.025626769 | AA55: =FALSE() -> FALSE | AB55: =FALSE() -> FALSE | AC55: =FALSE() -> FALSE | AD55: -1 | AE55: =FALSE() -> FALSE | AG55: =1/3*(U55+V55+W55) -> 0.4872493
A56: 54 | B56: 6.1807874 | C56: 76.420769 | D56: 81.300123 | E56: 132.20053 | F56: 230.0324 | G56: 256.32472 | H56: 239.08889 | I56: 37.54851 | J56: 87.267417 | K56: 28.265387 | L56: 16.209249 | M56: 2.8680874 | N56: 4.3622201 | O56: 1 | P56: 0.5407928 | Q56: 0.6868417 | R56: 0.00088904653 | S56: 0.94147603 | T56: 783.10168 | U56: 0.3999392 | V56: 0.21108614 | W56: 0.86512487 | X56: 0.49205007 | Y56: -1.5564508 | Z56: -0.9802291 | AA56: =FALSE() -> FALSE | AB56: =FALSE() -> FALSE | AC56: =FALSE() -> FALSE | AD56: -1 | AE56: =FALSE() -> FALSE | AG56: =1/3*(U56+V56+W56) -> 0.49205007
A57: 55 | B57: 4.0080042 | C57: 82.747816 | D57: 81.801068 | E57: 164.13299 | F57: 238.47538 | G57: 251.02493 | H57: 221.00974 | I57: 21.696504 | J57: 58.480579 | K57: 36.721963 | L57: 37.060913 | M57: 7.0812155 | N57: 2.842921 | O57: 1 | P57: 0.3822143 | Q57: 0.57725133 | R57: 0.0014788503 | S57: 0.94454607 | T57: 930.7186 | U57: 0.76924691 | V57: 0.31620797 | W57: 0.5967109 | X57: 0.56072193 | Y57: 0.22539792 | Z57: 0.26506669 | AA57: =TRUE() -> TRUE | AB57: =FALSE() -> FALSE | AC57: =FALSE() -> FALSE | AD57: 0 | AE57: =FALSE() -> FALSE | AF57: 0 | AG57: =1/3*(U57+V57+W57) -> 0.56072193
A58: 56 | B58: 5.645684 | C58: 77.048667 | D58: 99.638785 | E58: 154.81556 | F58: 228.89922 | G58: 227.25875 | H58: 258.79028 | I58: 25.537884 | J58: 42.440979 | K58: 17.693406 | L58: 29.785037 | M58: 5.2954201 | N58: 4.0763251 | O58: 1 | P58: 0.32951308 | Q58: 0.4674342 | R58: 0.00082046685 | S58: 0.95333443 | T58: 1025.5691 | U58: 0.3569978 | V58: 0.61713121 | W58: 0.42424288 | X58: 0.46612396 | Y58: 1.5473246 | Z58: 0.67292765 | AA58: =FALSE() -> FALSE | AB58: =FALSE() -> FALSE | AC58: =FALSE() -> FALSE | AD58: -1 | AE58: =FALSE() -> FALSE | AG58: =1/3*(U58+V58+W58) -> 0.46612396
A59: 57 | B59: 3.1774514 | C59: 84.75703 | D59: 85.169775 | E59: 163.62578 | F59: 234.69674 | G59: 251.987 | H59: 237.85625 | I59: 22.743354 | J59: 39.318484 | K59: 28.472623 | L59: 28.824585 | M59: 6.884319 | N59: 7.4989391 | O59: 1 | P59: 0.44495726 | Q59: 0.58528269 | R59: 0.00097094807 | S59: 0.95155666 | T59: 1002.8486 | U59: 0.45122215 | V59: 0.55625848 | W59: 0.46555595 | X59: 0.49101219 | Y59: 0.87271353 | Z59: 0.94406625 | AA59: =FALSE() -> FALSE | AB59: =FALSE() -> FALSE | AC59: =FALSE() -> FALSE | AD59: -1 | AE59: =FALSE() -> FALSE | AG59: =1/3*(U59+V59+W59) -> 0.49101219
A60: 58 | B60: 4.4060461 | C60: 84.089346 | D60: 82.11966 | E60: 136.11079 | F60: 234.19417 | G60: 254.79231 | H60: 244.77732 | I60: 40.605999 | J60: 52.483003 | K60: 19.454328 | L60: 24.55384 | M60: 7.1353072 | N60: 3.2678343 | O60: 1 | P60: 0.67976909 | Q60: 0.43263049 | R60: 0.00056783672 | S60: 0.94810975 | T60: 853.87758 | U60: 0.19881254 | V60: 0.43823241 | W60: 0.73643202 | X60: 0.45782566 | Y60: 0.37180788 | Z60: -1.3503602 | AA60: =FALSE() -> FALSE | AB60: =FALSE() -> FALSE | AC60: =FALSE() -> FALSE | AD60: -1 | AE60: =FALSE() -> FALSE | AG60: =1/3*(U60+V60+W60) -> 0.45782566
A61: 59 | B61: 4.5137312 | C61: 82.244624 | D61: 82.500292 | E61: 132.66035 | F61: 249.68364 | G61: 227.85248 | H61: 252.67046 | I61: 15.204588 | J61: 56.855383 | K61: 27.151654 | L61: 28.848358 | M61: 3.4908261 | N61: 7.1355923 | O61: 1 | P61: 0.5569215 | Q61: 0.41952441 | R61: 0.0008232108 | S61: 0.95013837 | T61: 949.57301 | U61: 0.35871593 | V61: 0.50769451 | W61: 0.56242765 | X61: 0.47627936 | Y61: 0.67811257 | Z61: 0.10862126 | AA61: =FALSE() -> FALSE | AB61: =FALSE() -> FALSE | AC61: =FALSE() -> FALSE | AD61: -1 | AE61: =FALSE() -> FALSE | AG61: =1/3*(U61+V61+W61) -> 0.47627936
A62: 60 | B62: 5.4298096 | C62: 77.380293 | D62: 85.445172 | E62: 152.44568 | F62: 224.53416 | G62: 244.60739 | H62: 241.29319 | I62: 15.836184 | J62: 87.748127 | K62: 16.937156 | L62: 25.291977 | M62: 5.2148426 | N62: 4.6714756 | O62: 1 | P62: 0.57968261 | Q62: 0.32100851 | R62: 0.00088529098 | S62: 0.94608677 | T62: 848.52129 | U62: 0.39758765 | V62: 0.36896309 | W62: 0.74617145 | X62: 0.50424073 | Y62: -0.57541459 | Z62: -0.45888365 | AA62: =FALSE() -> FALSE | AB62: =FALSE() -> FALSE | AC62: =FALSE() -> FALSE | AD62: -1 | AE62: =FALSE() -> FALSE | AG62: =1/3*(U62+V62+W62) -> 0.50424073
A63: 61 | B63: 3.9836395 | C63: 77.249419 | D63: 86.646514 | E63: 168.67066 | F63: 256.15405 | G63: 233.23946 | H63: 243.5076 | I63: 20.469546 | J63: 31.590453 | K63: 30.888659 | L63: 22.317046 | M63: 5.30763 | N63: 2.779649 | O63: 1 | P63: 0.37175194 | Q63: 0.46259708 | R63: 0.00075700128 | S63: 0.95650895 | T63: 1123.9978 | U63: 0.3172586 | V63: 0.7258304 | W63: 0.24526853 | X63: 0.42945251 | Y63: 2.6791554 | Z63: 1.2000056 | AA63: =FALSE() -> FALSE | AB63: =FALSE() -> FALSE | AC63: =FALSE() -> FALSE | AD63: -1 | AE63: =FALSE() -> FALSE | AG63: =1/3*(U63+V63+W63) -> 0.42945251
A64: 62 | B64: 3.5297342 | C64: 77.099546 | D64: 82.222664 | E64: 135.22586 | F64: 228.98205 | G64: 222.31091 | H64: 251.95046 | I64: 26.20342 | J64: 59.697192 | K64: 27.79984 | L64: 15.177931 | M64: 4.4493675 | N64: 3.6324141 | O64: 1 | P64: 0.483183 | Q64: 0.59851451 | R64: 0.00065303055 | S64: 0.95072247 | T64: 949.61509 | U64: 0.25215696 | V64: 0.52769483 | W64: 0.56235114 | X64: 0.44740098 | Y64: 1.1066018 | Z64: -0.39877101 | AA64: =FALSE() -> FALSE | AB64: =FALSE() -> FALSE | AC64: =FALSE() -> FALSE | AD64: -1 | AE64: =FALSE() -> FALSE | AG64: =1/3*(U64+V64+W64) -> 0.44740098
A65: 63 | B65: 6.7347252 | C65: 80.400959 | D65: 89.105294 | E65: 142.27718 | F65: 256.94911 | G65: 250.99502 | H65: 254.16254 | I65: 21.764983 | J65: 72.148471 | K65: 15.338689 | L65: 27.78775 | M65: 4.9043274 | N65: 4.7357593 | O65: 1 | P65: 0.33721437 | Q65: 0.61111736 | R65: 0.00099348531 | S65: 0.94794493 | T65: 870.15129 | U65: 0.46533392 | V65: 0.43258852 | W65: 0.70684131 | X65: 0.53492125 | Y65: -0.43874006 | Z65: 0.055148931 | AA65: =FALSE() -> FALSE | AB65: =FALSE() -> FALSE | AC65: =FALSE() -> FALSE | AD65: -1 | AE65: =FALSE() -> FALSE | AG65: =1/3*(U65+V65+W65) -> 0.53492125
...

Sheet pareto
A1: idx | B1: t2_days | C1: T3_C | D1: T4_C | E1: T5_C | F1: T6_C | G1: T7_C | H1: T8_C | I1: t3_min | J1: t4_min | K1: t5_min | L1: t6_min | M1: t7_min | N1: t8_min | O1: RH3 | P1: RH4 | Q1: RH5 | R1: C_gross | S1: J_gross | T1: R_raw | U1: C_norm | V1: J_norm | W1: R_norm | X1: Phi | Y1: PC1 | Z1: PC2 | AA1: is_pareto | AB1: is_mario | AC1: is_exp_test | AD1: cluster_id
A2: 28 | B2: 6.4669778 | C2: 84.025854 | D2: 94.352801 | E2: 142.39477 | F2: 245.57052 | G2: 237.27048 | H2: 238.61842 | I2: 18.520511 | J2: 36.402973 | K2: 25.780782 | L2: 23.892825 | M2: 3.1279117 | N2: 3.3569109 | O2: 1 | P2: 0.43144733 | Q2: 0.31120952 | R2: 0.00064365513 | S2: 0.95677743 | T2: 1034.4965 | U2: 0.24628651 | V2: 0.73502345 | W2: 0.40801007 | X2: 0.46310667 | Y2: 2.3978782 | Z2: 0.2654618 | AA2: =TRUE() -> TRUE | AB2: =FALSE() -> FALSE | AC2: =FALSE() -> FALSE | AD2: 1
A3: 52 | B3: 5.0023393 | C3: 84.3358 | D3: 96.015325 | E3: 152.19579 | F3: 238.56374 | G3: 221.6748 | H3: 228.20699 | I3: 16.180893 | J3: 80.652038 | K3: 12.816228 | L3: 28.766984 | M3: 4.5447249 | N3: 2.692847 | O3: 1 | P3: 0.50629799 | Q3: 0.6542666 | R3: 0.00089989234 | S3: 0.94843248 | T3: 823.00363 | U3: 0.40673035 | V3: 0.44928294 | W3: 0.79257057 | X3: 0.54952795 | Y3: -0.47323554 | Z3: -0.53330993 | AA3: =TRUE() -> TRUE | AB3: =FALSE() -> FALSE | AC3: =FALSE() -> FALSE | AD3: 2
A4: 55 | B4: 4.0080042 | C4: 82.747816 | D4: 81.801068 | E4: 164.13299 | F4: 238.47538 | G4: 251.02493 | H4: 221.00974 | I4: 21.696504 | J4: 58.480579 | K4: 36.721963 | L4: 37.060913 | M4: 7.0812155 | N4: 2.842921 | O4: 1 | P4: 0.3822143 | Q4: 0.57725133 | R4: 0.0014788503 | S4: 0.94454607 | T4: 930.7186 | U4: 0.76924691 | V4: 0.31620797 | W4: 0.5967109 | X4: 0.56072193 | Y4: -1.5010438 | Z4: 1.8677963 | AA4: =TRUE() -> TRUE | AB4: =FALSE() -> FALSE | AC4: =FALSE() -> FALSE | AD4: 0
A5: 66 | B5: 3.7087228 | C5: 82.992962 | D5: 84.581683 | E5: 132.58773 | F5: 235.10266 | G5: 231.25926 | H5: 247.4513 | I5: 42.196313 | J5: 88.950142 | K5: 19.229731 | L5: 18.956758 | M5: 3.3183632 | N5: 7.4883024 | O5: 1 | P5: 0.46050981 | Q5: 0.49729346 | R5: 0.00079811936 | S5: 0.94118878 | T5: 708.92576 | U5: 0.34300484 | V5: 0.20125064 | W5: 1 | X5: 0.51475183 | Y5: -1.8588808 | Z5: -1.7564675 | AA5: =TRUE() -> TRUE | AB5: =FALSE() -> FALSE | AC5: =FALSE() -> FALSE | AD5: 0
A6: 86 | B6: 6.2808129 | C6: 81.594277 | D6: 88.554241 | E6: 143.24676 | F6: 228.52299 | G6: 243.94659 | H6: 238.83717 | I6: 17.517534 | J6: 65.892208 | K6: 34.459487 | L6: 28.056882 | M6: 6.8802747 | N6: 7.1397354 | O6: 1 | P6: 0.32397907 | Q6: 0.4544851 | R6: 0.0014747654 | S6: 0.94501638 | T6: 891.93314 | U6: 0.76668917 | V6: 0.33231169 | W6: 0.66723506 | X6: 0.5887453 | Y6: -1.673389 | Z6: 1.6080467 | AA6: =TRUE() -> TRUE | AB6: =FALSE() -> FALSE | AC6: =FALSE() -> FALSE | AD6: 0
A7: 89 | B7: 4.7386843 | C7: 84.514666 | D7: 97.393883 | E7: 154.8698 | F7: 221.34353 | G7: 220.47841 | H7: 256.17322 | I7: 22.67923 | J7: 44.592737 | K7: 20.708961 | L7: 31.91396 | M7: 5.9566159 | N7: 5.743588 | O7: 1 | P7: 0.36340639 | Q7: 0.41459565 | R7: 0.00092423468 | S7: 0.95179932 | T7: 963.08962 | U7: 0.42197239 | V7: 0.56456721 | W7: 0.53785021 | X7: 0.50812994 | Y7: 0.75540529 | Z7: 0.54267983 | AA7: =TRUE() -> TRUE | AB7: =FALSE() -> FALSE | AC7: =FALSE() -> FALSE | AD7: 2
A8: 95 | B8: 6.1616074 | C8: 83.398063 | D8: 97.000245 | E8: 145.54204 | F8: 240.72116 | G8: 225.68885 | H8: 227.21683 | I8: 30.0259 | J8: 33.307287 | K8: 32.569418 | L8: 20.390466 | M8: 4.1113617 | N8: 2.6241415 | O8: 1 | P8: 0.3381121 | Q8: 0.66628945 | R8: 0.00081638953 | S8: 0.95372016 | T8: 1001.3726 | U8: 0.35444477 | V8: 0.63033891 | W8: 0.46823978 | X8: 0.48434115 | Y8: 1.4544183 | Z8: 0.50818565 | AA8: =TRUE() -> TRUE | AB8: =FALSE() -> FALSE | AC8: =FALSE() -> FALSE | AD8: 1
A9: 96 | B9: 5.7155931 | C9: 79.233066 | D9: 98.807563 | E9: 131.696 | F9: 257.2152 | G9: 224.70659 | H9: 244.90538 | I9: 18.968482 | J9: 42.618266 | K9: 28.877937 | L9: 35.02532 | M9: 2.9571197 | N9: 6.8082299 | O9: 1 | P9: 0.40254702 | Q9: 0.34955433 | R9: 0.00098077603 | S9: 0.95077061 | T9: 965.32792 | U9: 0.45737596 | V9: 0.52934303 | W9: 0.53378026 | X9: 0.50683308 | Y9: 0.52373997 | Z9: 0.70832179 | AA9: =TRUE() -> TRUE | AB9: =FALSE() -> FALSE | AC9: =FALSE() -> FALSE | AD9: 2
A10: 97 | B10: 4.8208927 | C10: 83.507607 | D10: 85.956074 | E10: 133.54839 | F10: 225.93071 | G10: 248.03698 | H10: 249.35819 | I10: 17.867468 | J10: 82.849661 | K10: 34.349061 | L10: 34.992675 | M10: 6.3503155 | N10: 4.2353908 | O10: 1 | P10: 0.44600578 | Q10: 0.49165852 | R10: 0.0014859453 | S10: 0.94085628 | T10: 812.80509 | U10: 0.77368953 | V10: 0.18986554 | W10: 0.81111473 | X10: 0.5915566 | Y10: -2.6987296 | Z10: 1.0280945 | AA10: =TRUE() -> TRUE | AB10: =FALSE() -> FALSE | AC10: =FALSE() -> FALSE | AD10: 0
A11: 101 | B11: 5.4861482 | C11: 82.951645 | D11: 86.580758 | E11: 131.27555 | F11: 248.04057 | G11: 240.403 | H11: 256.49907 | I11: 28.683177 | J11: 87.80071 | K11: 31.840599 | L11: 16.912591 | M11: 6.6861277 | N11: 5.2684513 | O11: 1 | P11: 0.41699828 | Q11: 0.55728807 | R11: 0.0012098258 | S11: 0.94145007 | T11: 757.01795 | U11: 0.60079627 | V11: 0.21019735 | W11: 0.91255329 | X11: 0.57451564 | Y11: -2.391488 | Z11: -0.17333374 | AA11: =TRUE() -> TRUE | AB11: =FALSE() -> FALSE | AC11: =FALSE() -> FALSE | AD11: 0
A12: 105 | B12: 6.048778 | C12: 79.796784 | D12: 99.91338 | E12: 145.48327 | F12: 252.64947 | G12: 229.39412 | H12: 237.10318 | I12: 19.556207 | J12: 60.99687 | K12: 22.10249 | L12: 18.915362 | M12: 4.6270341 | N12: 4.6293107 | O12: 1 | P12: 0.32714054 | Q12: 0.49080543 | R12: 0.00090766742 | S12: 0.95179804 | T12: 922.0204 | U12: 0.41159874 | V12: 0.56452333 | W12: 0.61252696 | X12: 0.52954968 | Y12: 0.53679917 | Z12: 0.21952087 | AA12: =TRUE() -> TRUE | AB12: =FALSE() -> FALSE | AC12: =FALSE() -> FALSE | AD12: 2
A13: 109 | B13: 5.6322824 | C13: 79.833547 | D13: 97.606057 | E13: 137.0002 | F13: 229.09553 | G13: 233.56152 | H13: 230.39397 | I13: 29.858979 | J13: 65.725516 | K13: 16.682501 | L13: 13.61674 | M13: 2.6330875 | N13: 7.3658678 | O13: 1 | P13: 0.39207274 | Q13: 0.61171478 | R13: 0.00069817019 | S13: 0.95063197 | T13: 886.05283 | U13: 0.28042131 | V13: 0.52459601 | W13: 0.6779273 | X13: 0.49431487 | Y13: 0.60925103 | Z13: -0.6844633 | AA13: =TRUE() -> TRUE | AB13: =FALSE() -> FALSE | AC13: =TRUE() -> TRUE | AD13: 2
A14: 113 | B14: 4.7015405 | C14: 83.622841 | D14: 85.720744 | E14: 153.6838 | F14: 252.00285 | G14: 245.37649 | H14: 246.08898 | I14: 16.555989 | J14: 62.393053 | K14: 33.462319 | L14: 16.907657 | M14: 7.0991277 | N14: 3.5792634 | O14: 1 | P14: 0.35245675 | Q14: 0.38427716 | R14: 0.0010356601 | S14: 0.9497983 | T14: 934.07305 | U14: 0.49174181 | V14: 0.49605017 | W14: 0.59061145 | X14: 0.52613448 | Y14: 0.096098477 | Z14: 0.64788179 | AA14: =TRUE() -> TRUE | AB14: =FALSE() -> FALSE | AC14: =FALSE() -> FALSE | AD14: 2
A15: 122 | B15: 6.9210246 | C15: 77.971468 | D15: 87.459741 | E15: 143.84142 | F15: 223.80292 | G15: 252.41617 | H15: 250.73168 | I15: 15.008563 | J15: 74.57174 | K15: 27.651008 | L15: 31.31607 | M15: 6.7848878 | N15: 7.0670805 | O15: 1 | P15: 0.4552287 | Q15: 0.54566513 | R15: 0.0014408055 | S15: 0.94438852 | T15: 883.05548 | U15: 0.74542506 | V15: 0.31081313 | W15: 0.68337743 | X15: 0.57987187 | Y15: -1.7346756 | Z15: 1.4318902 | AA15: =TRUE() -> TRUE | AB15: =FALSE() -> FALSE | AC15: =FALSE() -> FALSE | AD15: 0
A16: 125 | B16: 3.0566768 | C16: 84.505943 | D16: 97.861546 | E16: 160.82685 | F16: 251.56917 | G16: 242.12004 | H16: 225.95542 | I16: 31.23522 | J16: 59.570439 | K16: 29.855485 | L16: 24.339394 | M16: 6.3497139 | N16: 3.4819806 | O16: 1 | P16: 0.34583053 | Q16: 0.66248032 | R16: 0.0010925359 | S16: 0.9467262 | T16: 867.20994 | U16: 0.52735478 | V16: 0.39085806 | W16: 0.7121896 | X16: 0.54346748 | Y16: -0.8147477 | Z16: 0.3122903 | AA16: =TRUE() -> TRUE | AB16: =FALSE() -> FALSE | AC16: =FALSE() -> FALSE | AD16: 2
A17: 134 | B17: 3.7848535 | C17: 77.46891 | D17: 97.091417 | E17: 166.40296 | F17: 249.6676 | G17: 230.99333 | H17: 258.71479 | I17: 20.386752 | J17: 72.809622 | K17: 33.639096 | L17: 17.09407 | M17: 4.4399211 | N17: 4.7618662 | O17: 1 | P17: 0.43109077 | Q17: 0.461166 | R17: 0.0010841329 | S17: 0.94695309 | T17: 876.1755 | U17: 0.52209326 | V17: 0.39862689 | W17: 0.69588739 | X17: 0.53886918 | Y17: -0.71386574 | Z17: 0.35095151 | AA17: =TRUE() -> TRUE | AB17: =FALSE() -> FALSE | AC17: =FALSE() -> FALSE | AD17: 2
A18: 156 | B18: 5.9191947 | C18: 84.359197 | D18: 84.538346 | E18: 150.90195 | F18: 226.24115 | G18: 246.59129 | H18: 237.94145 | I18: 28.1466 | J18: 61.131753 | K18: 30.982112 | L18: 19.884354 | M18: 5.1810483 | N18: 7.129188 | O18: 1 | P18: 0.32291988 | Q18: 0.39121218 | R18: 0.0011154319 | S18: 0.94673938 | T18: 880.97455 | U18: 0.54169123 | V18: 0.3913093 | W18: 0.68716122 | X18: 0.54005392 | Y18: -0.7761872 | Z18: 0.47388528 | AA18: =TRUE() -> TRUE | AB18: =FALSE() -> FALSE | AC18: =FALSE() -> FALSE | AD18: 2
A19: 168 | B19: 3.1621916 | C19: 83.055614 | D19: 91.560485 | E19: 137.3323 | F19: 231.69722 | G19: 230.72329 | H19: 244.21275 | I19: 24.471658 | J19: 84.795384 | K19: 15.018471 | L19: 29.58477 | M19: 4.3424092 | N19: 6.0823314 | O19: 1 | P19: 0.36280895 | Q19: 0.66531236 | R19: 0.00096510034 | S19: 0.9446372 | T19: 787.19346 | U19: 0.44756057 | V19: 0.3193284 | W19: 0.85768473 | X19: 0.54152457 | Y19: -1.2995387 | Z19: -0.65289078 | AA19: =TRUE() -> TRUE | AB19: =FALSE() -> FALSE | AC19: =FALSE() -> FALSE | AD19: 0
A20: 170 | B20: 3.9631283 | C20: 84.499712 | D20: 96.619588 | E20: 164.98934 | F20: 235.51333 | G20: 237.79872 | H20: 220.01806 | I20: 23.823421 | J20: 40.462416 | K20: 32.078134 | L20: 16.816671 | M20: 5.0557464 | N20: 6.9092367 | O20: 1 | P20: 0.30402486 | Q20: 0.30329812 | R20: 0.00082812366 | S20: 0.95350943 | T20: 996.70937 | U20: 0.36179214 | V20: 0.62312322 | W20: 0.47671893 | X20: 0.48721143 | Y20: 1.3750797 | Z20: 0.5085988 | AA20: =TRUE() -> TRUE | AB20: =FALSE() -> FALSE | AC20: =FALSE() -> FALSE | AD20: 1
A21: 178 | B21: 5.8713575 | C21: 84.84621 | D21: 92.67348 | E21: 137.45168 | F21: 237.96099 | G21: 237.42261 | H21: 225.55854 | I21: 26.436422 | J21: 89.070293 | K21: 17.852908 | L21: 20.141873 | M21: 4.2107796 | N21: 4.9639856 | O21: 1 | P21: 0.53177508 | Q21: 0.59557489 | R21: 0.0009235709 | S21: 0.94447929 | T21: 757.14658 | U21: 0.42155676 | V21: 0.31392126 | W21: 0.91231939 | X21: 0.5492658 | Y21: -1.4173572 | Z21: -0.98257375 | AA21: =TRUE() -> TRUE | AB21: =FALSE() -> FALSE | AC21: =FALSE() -> FALSE | AD21: 0
A22: 215 | B22: 6.0905761 | C22: 84.083656 | D22: 95.280679 | E22: 165.24759 | F22: 221.73185 | G22: 220.75405 | H22: 246.19598 | I22: 16.168222 | J22: 47.462425 | K22: 13.724453 | L22: 28.547707 | M22: 4.1514993 | N22: 5.6666103 | O22: 1 | P22: 0.58839515 | Q22: 0.51187517 | R22: 0.00070334213 | S22: 0.95560093 | T22: 1003.0169 | U22: 0.28365974 | V22: 0.69473884 | W22: 0.46524983 | X22: 0.48121614 | Y22: 1.9335608 | Z22: 0.21383768 | AA22: =TRUE() -> TRUE | AB22: =FALSE() -> FALSE | AC22: =FALSE() -> FALSE | AD22: 1
A23: 216 | B23: 2.9425651 | C23: 83.812395 | D23: 91.887812 | E23: 140.12194 | F23: 228.70568 | G23: 231.30492 | H23: 258.50944 | I23: 28.512787 | J23: 50.321888 | K23: 23.468363 | L23: 13.22757 | M23: 5.2546484 | N23: 5.1514471 | O23: 1 | P23: 0.59249537 | Q23: 0.63985837 | R23: 0.00054866191 | S23: 0.95349899 | T23: 931.9886 | U23: 0.18680616 | V23: 0.62276577 | W23: 0.59440163 | X23: 0.46799119 | Y23: 1.5595587 | Z23: -0.77526296 | AA23: =TRUE() -> TRUE | AB23: =FALSE() -> FALSE | AC23: =FALSE() -> FALSE | AD23: 1
A24: 222 | B24: 3.8329862 | C24: 83.858017 | D24: 89.081919 | E24: 155.15431 | F24: 256.79307 | G24: 252.74739 | H24: 242.36776 | I24: 20.404323 | J24: 55.421416 | K24: 32.740924 | L24: 18.989013 | M24: 3.9430764 | N24: 2.7405426 | O24: 1 | P24: 0.49597246 | Q24: 0.61939247 | R24: 0.00090807786 | S24: 0.95131427 | T24: 937.55892 | U24: 0.41185574 | V24: 0.54795877 | W24: 0.58427305 | X24: 0.51469585 | Y24: 0.5718982 | Z24: 0.31350911 | AA24: =TRUE() -> TRUE | AB24: =FALSE() -> FALSE | AC24: =FALSE() -> FALSE | AD24: 2
A25: 226 | B25: 4.2542719 | C25: 83.996755 | D25: 90.056126 | E25: 152.76164 | F25: 244.27788 | G25: 222.14609 | H25: 237.69571 | I25: 21.080459 | J25: 45.046977 | K25: 31.5689 | L25: 28.118898 | M25: 3.8971346 | N25: 4.1757914 | O25: 1 | P25: 0.34875393 | Q25: 0.61501102 | R25: 0.0010406772 | S25: 0.95132479 | T25: 973.43143 | U25: 0.49488328 | V25: 0.54831871 | W25: 0.51904553 | X25: 0.52074918 | Y25: 0.51687729 | Z25: 0.95705732 | AA25: =TRUE() -> TRUE | AB25: =FALSE() -> FALSE | AC25: =FALSE() -> FALSE | AD25: 2
... A41: 359 | B41: 3.2718921 | C41: 84.038151 | D41: 96.994654 | E41: 168.39867 | F41: 236.59286 | G41: 251.05761 | H41: 256.68352 | I41: 18.192657 | J41: 47.566874 | K41: 32.164401 | L41: 16.956661 | M41: 2.9123178 | N41: 2.7632646 | O41: 1 | P41: 0.48413003 | Q41: 0.51371405 | R41: 0.00079821564 | S41: 0.95477972 | T41: 981.08137 | U41: 0.34306512 | V41: 0.66661937 | W41: 0.50513555 | X41: 0.50494001 | Y41: 1.4983732 | Z41: 0.34070158 | AA41: =TRUE() -> TRUE | AB41: =FALSE() -> FALSE | AC41: =FALSE() -> FALSE | AD41: 1
A42: 384 | B42: 6.8111688 | C42: 80.917567 | D42: 80.214419 | E42: 164.4899 | F42: 223.97957 | G42: 255.54149 | H42: 238.911 | I42: 16.354826 | J42: 36.960485 | K42: 16.417182 | L42: 20.22207 | M42: 4.4427679 | N42: 4.4560178 | O42: 1 | P42: 0.58976695 | Q42: 0.59124353 | R42: 0.00049950639 | S42: 0.96008725 | T42: 1186.8184 | U42: 0.15602726 | V42: 0.84835525 | W42: 0.13104097 | X42: 0.37847449 | Y42: 4.0473653 | Z42: 0.90639344 | AA42: =TRUE() -> TRUE | AB42: =FALSE() -> FALSE | AC42: =TRUE() -> TRUE | AD42: 1
A43: 386 | B43: 2.8242224 | C43: 82.303728 | D43: 99.322331 | E43: 132.14956 | F43: 256.35589 | G43: 221.58128 | H43: 242.80709 | I43: 20.250098 | J43: 43.014219 | K43: 14.861997 | L43: 20.90091 | M43: 3.2967867 | N43: 5.1605359 | O43: 1 | P43: 0.36217699 | Q43: 0.34327465 | R43: 0.00044882752 | S43: 0.95825268 | T43: 1017.2984 | U43: 0.1242945 | V43: 0.78553742 | W43: 0.43928155 | X43: 0.44970449 | Y43: 2.8818477 | Z43: -0.41256618 | AA43: =TRUE() -> TRUE | AB43: =FALSE() -> FALSE | AC43: =FALSE() -> FALSE | AD43: 1
A44: 391 | B44: 5.3018034 | C44: 82.863764 | D44: 99.10285 | E44: 168.06947 | F44: 234.12522 | G44: 253.31519 | H44: 250.65918 | I44: 22.539827 | J44: 68.22839 | K44: 20.487308 | L44: 16.795241 | M44: 7.3941458 | N44: 7.2241999 | O44: 1 | P44: 0.32191047 | Q44: 0.3215646 | R44: 0.00094789122 | S44: 0.94907724 | T44: 875.23624 | U44: 0.43678502 | V44: 0.47136036 | W44: 0.69759527 | X44: 0.53524688 | Y44: -0.17203528 | Z44: -0.026222221 | AA44: =TRUE() -> TRUE | AB44: =FALSE() -> FALSE | AC44: =FALSE() -> FALSE | AD44: 2
A45: 392 | B45: 3.7005918 | C45: 81.169222 | D45: 98.922118 | E45: 137.6768 | F45: 256.40679 | G45: 223.75254 | H45: 226.07759 | I45: 21.377021 | J45: 40.646157 | K45: 15.505931 | L45: 19.725691 | M45: 3.9556579 | N45: 4.6236014 | O45: 1 | P45: 0.49093304 | Q45: 0.37713233 | R45: 0.00043392995 | S45: 0.95854949 | T45: 1044.4994 | U45: 0.11496634 | V45: 0.79570056 | W45: 0.38982171 | X45: 0.4334962 | Y45: 3.1173443 | Z45: -0.27126884 | AA45: =TRUE() -> TRUE | AB45: =FALSE() -> FALSE | AC45: =FALSE() -> FALSE | AD45: 1
A46: 397 | B46: 3.7740559 | C46: 83.714771 | D46: 97.139014 | E46: 138.51548 | F46: 239.66942 | G46: 259.99272 | H46: 243.83453 | I46: 19.970617 | J46: 61.086584 | K46: 16.567465 | L46: 19.424923 | M46: 4.7737347 | N46: 6.945953 | O46: 1 | P46: 0.5482045 | Q46: 0.40239532 | R46: 0.00062951177 | S46: 0.95264883 | T46: 900.33403 | U46: 0.23743059 | V46: 0.59365559 | W46: 0.6519596 | X46: 0.49434859 | Y46: 1.0902343 | Z46: -0.75636944 | AA46: =TRUE() -> TRUE | AB46: =FALSE() -> FALSE | AC46: =FALSE() -> FALSE | AD46: 2
A47: 409 | B47: 5.1260257 | C47: 84.507618 | D47: 99.093647 | E47: 166.66748 | F47: 245.18203 | G47: 223.19868 | H47: 237.90918 | I47: 18.337213 | J47: 41.238988 | K47: 13.217202 | L47: 14.31232 | M47: 4.6560421 | N47: 5.5261428 | O47: 1 | P47: 0.39809257 | Q47: 0.33603457 | R47: 0.00045271952 | S47: 0.96071291 | T47: 1081.517 | U47: 0.12673149 | V47: 0.86977862 | W47: 0.32251193 | X47: 0.43967401 | Y47: 3.5736269 | Z47: 0.078118665 | AA47: =TRUE() -> TRUE | AB47: =FALSE() -> FALSE | AC47: =FALSE() -> FALSE | AD47: 1
A48: 424 | B48: 4.0635443 | C48: 84.886551 | D48: 92.576492 | E48: 130.64958 | F48: 235.60241 | G48: 234.12668 | H48: 227.83009 | I48: 37.974907 | J48: 63.667708 | K48: 15.652891 | L48: 22.568799 | M48: 6.867915 | N48: 6.7455682 | O48: 1 | P48: 0.54583065 | Q48: 0.56171936 | R48: 0.0006956719 | S48: 0.94682153 | T48: 810.20362 | U48: 0.27885699 | V48: 0.39412209 | W48: 0.81584502 | X48: 0.4962747 | Y48: -0.32404234 | Z48: -1.2769803 | AA48: =TRUE() -> TRUE | AB48: =FALSE() -> FALSE | AC48: =FALSE() -> FALSE | AD48: 2
A49: 425 | B49: 3.2008991 | C49: 83.984532 | D49: 97.201238 | E49: 132.19147 | F49: 252.52904 | G49: 251.29009 | H49: 255.80433 | I49: 37.506912 | J49: 77.661268 | K49: 35.953687 | L49: 36.103387 | M49: 5.2036503 | N49: 4.5816949 | O49: 1 | P49: 0.33033119 | Q49: 0.58638154 | R49: 0.0015895266 | S49: 0.93793411 | T49: 791.54393 | U49: 0.83854732 | V49: 0.08980714 | W49: 0.8497742 | X49: 0.59270955 | Y49: -3.4077081 | Z49: 1.1410432 | AA49: =TRUE() -> TRUE | AB49: =FALSE() -> FALSE | AC49: =FALSE() -> FALSE | AD49: 0
A50: 452 | B50: 2.9876838 | C50: 81.583828 | D50: 96.548496 | E50: 144.83329 | F50: 232.54044 | G50: 220.27682 | H50: 237.17458 | I50: 16.622004 | J50: 30.227529 | K50: 30.905746 | L50: 24.284483 | M50: 3.4085031 | N50: 7.3817305 | O50: 1 | P50: 0.39408281 | Q50: 0.51259697 | R50: 0.00073129955 | S50: 0.95681326 | T50: 1055.6751 | U50: 0.30116537 | V50: 0.73625011 | W50: 0.36950076 | X50: 0.46897208 | Y50: 2.3494752 | Z50: 0.67464697 | AA50: =TRUE() -> TRUE | AB50: =FALSE() -> FALSE | AC50: =FALSE() -> FALSE | AD50: 1
A51: 455 | B51: 2.2071312 | C51: 83.636555 | D51: 90.731946 | E51: 147.81035 | F51: 225.87168 | G51: 236.87457 | H51: 235.04859 | I51: 29.589485 | J51: 79.610038 | K51: 28.559607 | L51: 25.264334 | M51: 3.171858 | N51: 4.3793144 | O51: 1 | P51: 0.35091366 | Q51: 0.53551318 | R51: 0.0010775776 | S51: 0.94353581 | T51: 791.98656 | U51: 0.51798863 | V51: 0.28161547 | W51: 0.84896936 | X51: 0.54952449 | Y51: -1.6414635 | Z51: -0.30087749 | AA51: =TRUE() -> TRUE | AB51: =FALSE() -> FALSE | AC51: =TRUE() -> TRUE | AD51: 0
A52: 474 | B52: 6.0962594 | C52: 78.582576 | D52: 99.192763 | E52: 144.93917 | F52: 259.38801 | G52: 228.68055 | H52: 256.9125 | I52: 15.039257 | J52: 37.222055 | K52: 19.104489 | L52: 17.588348 | M52: 5.8590617 | N52: 6.7738269 | O52: 1 | P52: 0.64341373 | Q52: 0.41842528 | R52: 0.00049776333 | S52: 0.95939683 | T52: 1084.8803 | U52: 0.15493584 | V52: 0.82471448 | W52: 0.3163965 | X52: 0.43201561 | Y52: 3.3374211 | Z52: 0.20992429 | AA52: =TRUE() -> TRUE | AB52: =FALSE() -> FALSE | AC52: =FALSE() -> FALSE | AD52: 1
A53: 481 | B53: 4.9210304 | C53: 84.48094 | D53: 80.857769 | E53: 162.61384 | F53: 237.66723 | G53: 256.08543 | H53: 238.40325 | I53: 41.790234 | J53: 68.062085 | K53: 14.684704 | L53: 13.022317 | M53: 4.2911848 | N53: 4.9051648 | O53: 1 | P53: 0.50408154 | Q53: 0.38054078 | R53: 0.00054982588 | S53: 0.94819228 | T53: 807.92755 | U53: 0.18753499 | V53: 0.44105821 | W53: 0.81998362 | X53: 0.48285894 | Y53: 0.13650239 | Z53: -1.7085201 | AA53: =TRUE() -> TRUE | AB53: =FALSE() -> FALSE | AC53: =FALSE() -> FALSE | AD53: 2
A54: 486 | B54: 6.1682364 | C54: 78.548235 | D54: 95.559391 | E54: 163.12361 | F54: 252.32184 | G54: 222.04625 | H54: 250.81116 | I54: 18.863931 | J54: 53.33864 | K54: 32.330998 | L54: 22.807158 | M54: 4.8078814 | N54: 6.4497428 | O54: 1 | P54: 0.49470462 | Q54: 0.47683242 | R54: 0.0011094711 | S54: 0.94991062 | T54: 962.13031 | U54: 0.53795881 | V54: 0.49989613 | W54: 0.53959454 | X54: 0.52581649 | Y54: 0.12848502 | Z54: 1.0620609 | AA54: =TRUE() -> TRUE | AB54: =FALSE() -> FALSE | AC54: =FALSE() -> FALSE | AD54: 2
A55: 490 | B55: 3.6026621 | C55: 83.135556 | D55: 96.406663 | E55: 148.00126 | F55: 222.27735 | G55: 240.24688 | H55: 249.87891 | I55: 16.651861 | J55: 47.338933 | K55: 31.741487 | L55: 17.385879 | M55: 6.5142365 | N55: 7.3321941 | O55: 1 | P55: 0.39225312 | Q55: 0.60133122 | R55: 0.00094309608 | S55: 0.95312228 | T55: 969.43906 | U55: 0.43378252 | V55: 0.60986679 | W55: 0.52630492 | X55: 0.52331808 | Y55: 0.91862891 | Z55: 0.67080124 | AA55: =TRUE() -> TRUE | AB55: =FALSE() -> FALSE | AC55: =FALSE() -> FALSE | AD55: 2
...

Sheet exp_tests
A1: idx | B1: t2_days | C1: T3_C | D1: T4_C | E1: T5_C | F1: T6_C | G1: T7_C | H1: T8_C | I1: t3_min | J1: t4_min | K1: t5_min | L1: t6_min | M1: t7_min | N1: t8_min | O1: RH3 | P1: RH4 | Q1: RH5 | R1: C_gross | S1: J_gross | T1: R_raw | U1: C_norm | V1: J_norm | W1: R_norm | X1: Phi | Y1: PC1 | Z1: PC2 | AA1: is_pareto | AB1: is_mario | AC1: is_exp_test | AD1: cluster_id
A2: 109 | B2: 5.6322824 | C2: 79.833547 | D2: 97.606057 | E2: 137.0002 | F2: 229.09553 | G2: 233.56152 | H2: 230.39397 | I2: 29.858979 | J2: 65.725516 | K2: 16.682501 | L2: 13.61674 | M2: 2.6330875 | N2: 7.3658678 | O2: 1 | P2: 0.39207274 | Q2: 0.61171478 | R2: 0.00069817019 | S2: 0.95063197 | T2: 886.05283 | U2: 0.28042131 | V2: 0.52459601 | W2: 0.6779273 | X2: 0.49431487 | Y2: 0.60925103 | Z2: -0.6844633 | AA2: =TRUE() -> TRUE | AB2: =FALSE() -> FALSE | AC2: =TRUE() -> TRUE | AD2: 2
A3: 384 | B3: 6.8111688 | C3: 80.917567 | D3: 80.214419 | E3: 164.4899 | F3: 223.97957 | G3: 255.54149 | H3: 238.911 | I3: 16.354826 | J3: 36.960485 | K3: 16.417182 | L3: 20.22207 | M3: 4.4427679 | N3: 4.4560178 | O3: 1 | P3: 0.58976695 | Q3: 0.59124353 | R3: 0.00049950639 | S3: 0.96008725 | T3: 1186.8184 | U3: 0.15602726 | V3: 0.84835525 | W3: 0.13104097 | X3: 0.37847449 | Y3: 4.0473653 | Z3: 0.90639344 | AA3: =TRUE() -> TRUE | AB3: =FALSE() -> FALSE | AC3: =TRUE() -> TRUE | AD3: 1
A4: 455 | B4: 2.2071312 | C4: 83.636555 | D4: 90.731946 | E4: 147.81035 | F4: 225.87168 | G4: 236.87457 | H4: 235.04859 | I4: 29.589485 | J4: 79.610038 | K4: 28.559607 | L4: 25.264334 | M4: 3.171858 | N4: 4.3793144 | O4: 1 | P4: 0.35091366 | Q4: 0.53551318 | R4: 0.0010775776 | S4: 0.94353581 | T4: 791.98656 | U4: 0.51798863 | V4: 0.28161547 | W4: 0.84896936 | X4: 0.54952449 | Y4: -1.6414635 | Z4: -0.30087749 | AA4: =TRUE() -> TRUE | AB4: =FALSE() -> FALSE | AC4: =TRUE() -> TRUE | AD4: 0
A5: 600 | B5: 5.9126029 | C5: 84.632031 | D5: 80.735064 | E5: 169.15082 | F5: 229.63031 | G5: 254.40048 | H5: 236.10511 | I5: 15.339013 | J5: 72.558485 | K5: 18.78874 | L5: 26.358694 | M5: 4.2492547 | N5: 5.6763584 | O5: 1 | P5: 0.39330171 | Q5: 0.50426143 | R5: 0.0010312835 | S5: 0.94891683 | T5: 918.94066 | U5: 0.48900137 | V5: 0.46586768 | W5: 0.61812688 | X5: 0.52433198 | Y5: -0.096977016 | Z5: 0.51521896 | AA5: =TRUE() -> TRUE | AB5: =FALSE() -> FALSE | AC5: =TRUE() -> TRUE | AD5: 2
A6: 851 | B6: 5.8738045 | C6: 80.606139 | D6: 90.785336 | E6: 163.82935 | F6: 240.79232 | G6: 259.61711 | H6: 257.60125 | I6: 20.290997 | J6: 64.827243 | K6: 34.857755 | L6: 23.155422 | M6: 5.0771794 | N6: 7.39698 | O6: 1 | P6: 0.42719606 | Q6: 0.54388054 | R6: 0.0013755486 | S6: 0.94603896 | T6: 900.02884 | U6: 0.70456418 | V6: 0.36732626 | W6: 0.65251452 | X6: 0.57480165 | Y6: -1.2895148 | Z6: 1.3803942 | AA6: =TRUE() -> TRUE | AB6: =FALSE() -> FALSE | AC6: =TRUE() -> TRUE | AD6: 0
A7: 1168 | B7: 2.2669799 | C7: 82.093273 | D7: 89.80354 | E7: 149.26164 | F7: 253.20761 | G7: 241.50547 | H7: 259.64007 | I7: 18.755869 | J7: 66.630059 | K7: 17.595905 | L7: 19.963726 | M7: 6.3336794 | N7: 6.6481492 | O7: 1 | P7: 0.32674299 | Q7: 0.66776936 | R7: 0.0007786786 | S7: 0.95122831 | T7: 902.23002 | U7: 0.33083193 | V7: 0.54501516 | W7: 0.64851209 | X7: 0.50811973 | Y7: 0.61424668 | Z7: -0.31826705 | AA7: =TRUE() -> TRUE | AB7: =FALSE() -> FALSE | AC7: =TRUE() -> TRUE | AD7: 2
A8: 1198 | B8: 5.4826682 | C8: 83.139213 | D8: 87.162423 | E8: 165.80621 | F8: 237.7396 | G8: 226.69068 | H8: 222.31615 | I8: 30.901598 | J8: 86.833856 | K8: 25.348505 | L8: 24.0937 | M8: 5.4177751 | N8: 3.8875671 | O8: 1 | P8: 0.31829324 | Q8: 0.43155745 | R8: 0.001236075 | S8: 0.94159834 | T8: 768.62746 | U8: 0.61723231 | V8: 0.2152745 | W8: 0.89144355 | X8: 0.57465012 | Y8: -2.3565226 | Z8: -0.012894157 | AA8: =TRUE() -> TRUE | AB8: =FALSE() -> FALSE | AC8: =TRUE() -> TRUE | AD8: 0
A9: 1873 | B9: 3.2255032 | C9: 84.112406 | D9: 82.398655 | E9: 155.4409 | F9: 254.03712 | G9: 253.44242 | H9: 233.8449 | I9: 19.817546 | J9: 30.126371 | K9: 15.039006 | L9: 12.564223 | M9: 4.7894836 | N9: 2.734081 | O9: 1 | P9: 0.62435639 | Q9: 0.66926287 | R9: 0.0002503227 | S9: 0.96451598 | T9: 1258.8857 | U9: 0 | V9: 1 | W9: 0 | X9: 0.33333333 | Y9: 5.56031 | Z9: 0.71775492 | AA9: =TRUE() -> TRUE | AB9: =FALSE() -> FALSE | AC9: =TRUE() -> TRUE | AD9: 1
A10: 2123 | B10: 3.2613943 | C10: 75.590812 | D10: 99.015394 | E10: 148.14738 | F10: 240.15312 | G10: 220.66436 | H10: 230.23518 | I10: 16.133067 | J10: 68.949827 | K10: 35.203915 | L10: 13.352039 | M10: 5.9674079 | N10: 3.0044984 | O10: 1 | P10: 0.61936173 | Q10: 0.65855985 | R10: 0.00090668446 | S10: 0.94945193 | T10: 898.70216 | U10: 0.41098326 | V10: 0.48418997 | W10: 0.65492685 | X10: 0.51670003 | Y10: 0.10510923 | Z10: 0.011543457 | AA10: =TRUE() -> TRUE | AB10: =FALSE() -> FALSE | AC10: =TRUE() -> TRUE | AD10: 2
A11: 2187 | B11: 6.701794 | C11: 81.57964 | D11: 95.101319 | E11: 156.07291 | F11: 258.65958 | G11: 239.09077 | H11: 248.26954 | I11: 20.359493 | J11: 67.43762 | K11: 27.765352 | L11: 16.392645 | M11: 7.2641587 | N11: 2.6489871 | O11: 1 | P11: 0.56089513 | Q11: 0.50778967 | R11: 0.00096389622 | S11: 0.94906922 | T11: 882.34115 | U11: 0.44680661 | V11: 0.47108562 | W11: 0.6846763 | X11: 0.53418951 | Y11: -0.16272288 | Z11: 0.069668369 | AA11: =TRUE() -> TRUE | AB11: =FALSE() -> FALSE | AC11: =TRUE() -> TRUE | AD11: 2
A12: 2229 | B12: 2.4011976 | C12: 76.457983 | D12: 94.299553 | E12: 156.76331 | F12: 224.72717 | G12: 250.80212 | H12: 240.50508 | I12: 15.756054 | J12: 48.079331 | K12: 34.038482 | L12: 30.943217 | M12: 7.4821828 | N12: 5.1275238 | O12: 1 | P12: 0.34685478 | Q12: 0.6788335 | R12: 0.0011588998 | S12: 0.94991066 | T12: 991.3671 | U12: 0.56890877 | V12: 0.49989757 | W12: 0.48643285 | X12: 0.51841306 | Y12: 0.2052688 | Z12: 1.4071326 | AA12: =TRUE() -> TRUE | AB12: =FALSE() -> FALSE | AC12: =TRUE() -> TRUE | AD12: 2
A13: 2504 | B13: 5.3940999 | C13: 78.053319 | D13: 99.283759 | E13: 161.10903 | F13: 241.8373 | G13: 249.2378 | H13: 240.77493 | I13: 39.485858 | J13: 89.696261 | K13: 35.736697 | L13: 28.59984 | M13: 5.9820157 | N13: 5.4199937 | O13: 1 | P13: 0.3604983 | Q13: 0.60356877 | R13: 0.001847375 | S13: 0.93591947 | T13: 804.97844 | U13: 1 | V13: 0.020823601 | W13: 0.82534604 | X13: 0.61538988 | Y13: -4.1133957 | Z13: 1.9751788 | AA13: =TRUE() -> TRUE | AB13: =FALSE() -> FALSE | AC13: =TRUE() -> TRUE | AD13: 0
... A16: 2746 | B16: 3.4184225 | C16: 81.051565 | D16: 95.061175 | E16: 132.92672 | F16: 242.60192 | G16: 257.96608 | H16: 225.62538 | I16: 16.269308 | J16: 51.851393 | K16: 15.378691 | L16: 27.293692 | M16: 3.7035657 | N16: 3.8755707 | O16: 1 | P16: 0.34180792 | Q16: 0.52999785 | R16: 0.0006204127 | S16: 0.95530776 | T16: 972.00129 | U16: 0.23173318 | V16: 0.68470028 | W16: 0.52164598 | X16: 0.47935981 | Y16: 1.8796601 | Z16: -0.25171629 | AA16: =TRUE() -> TRUE | AB16: =FALSE() -> FALSE | AC16: =TRUE() -> TRUE | AD16: 1
A17: 3000 | B17: 6 | C17: 80 | D17: 90 | E17: 130 | F17: 230 | G17: 240 | H17: 250 | I17: 30 | J17: 60 | K17: 25 | L17: 25 | M17: 5 | N17: 5 | O17: 1 | P17: 0.5 | Q17: 0.5 | R17: 0.00086899695 | S17: 0.94728409 | T17: 878.00189 | U17: 0.38738509 | V17: 0.40996079 | W17: 0.69256645 | X17: 0.49663744 | Y17: -0.21162111 | Z17: -0.28743864 | AA17: =FALSE() -> FALSE | AB17: =TRUE() -> TRUE | AC17: =TRUE() -> TRUE | AD17: -1

Sheet Panel_Raw
A1: idx | B1: schedule_label | C1: schedule_type | D1: replicate_id | E1: chef_id | F1: C_sens | G1: J_sens | H1: R_sens | I1: C_norm | J1: J_norm | K1: R_norm | L1: is_chef | M1: is_mario | N1: is_pareto | O1: is_exp_test | P1: cluster_id
A2: 109 | B2: Test schedule 109 | C2: Pareto test | D2: 1 | E2: 1 | F2: 2 | G2: 7 | H2: 7 | I2: 0.28042131 | J2: 0.52459601 | K2: 0.6779273 | L2: =FALSE() -> 0 | M2: =FALSE() -> 0 | N2: =TRUE() -> 1 | O2: =TRUE() -> 1 | P2: 2
A3: 109 | B3: Test schedule 109 | C3: Pareto test | D3: 1 | E3: 2 | F3: 4 | G3: 8 | H3: 6 | I3: 0.28042131 | J3: 0.52459601 | K3: 0.6779273 | L3: =FALSE() -> 0 | M3: =FALSE() -> 0 | N3: =TRUE() -> 1 | O3: =TRUE() -> 1 | P3: 2
A4: 109 | B4: Test schedule 109 | C4: Pareto test | D4: 1 | E4: 3 | F4: 3 | G4: 9 | H4: 7 | I4: 0.28042131 | J4: 0.52459601 | K4: 0.6779273 | L4: =FALSE() -> 0 | M4: =FALSE() -> 0 | N4: =TRUE() -> 1 | O4: =TRUE() -> 1 | P4: 2
A5: 109 | B5: Test schedule 109 | C5: Pareto test | D5: 1 | E5: 4 | F5: 3 | G5: 8 | H5: 6 | I5: 0.28042131 | J5: 0.52459601 | K5: 0.6779273 | L5: =FALSE() -> 0 | M5: =FALSE() -> 0 | N5: =TRUE() -> 1 | O5: =TRUE() -> 1 | P5: 2
A6: 109 | B6: Test schedule 109 | C6: Pareto test | D6: 1 | E6: 5 | F6: 3 | G6: 10 | H6: 7 | I6: 0.28042131 | J6: 0.52459601 | K6: 0.6779273 | L6: =FALSE() -> 0 | M6: =FALSE() -> 0 | N6: =TRUE() -> 1 | O6: =TRUE() -> 1 | P6: 2
A7: 109 | B7: Test schedule 109 | C7: Pareto test | D7: 1 | E7: 6 | F7: 3 | G7: 9 | H7: 7 | I7: 0.28042131 | J7: 0.52459601 | K7: 0.6779273 | L7: =FALSE() -> 0 | M7: =FALSE() -> 0 | N7: =TRUE() -> 1 | O7: =TRUE() -> 1 | P7: 2
A8: 109 | B8: Test schedule 109 | C8: Pareto test | D8: 1 | E8: 7 | F8: 5 | G8: 8 | H8: 7 | I8: 0.28042131 | J8: 0.52459601 | K8: 0.6779273 | L8: =FALSE() -> 0 | M8: =FALSE() -> 0 | N8: =TRUE() -> 1 | O8: =TRUE() -> 1 | P8: 2
A9: 109 | B9: Test schedule 109 | C9: Pareto test | D9: 1 | E9: 8 | F9: 2 | G9: 9 | H9: 9 | I9: 0.28042131 | J9: 0.52459601 | K9: 0.6779273 | L9: =FALSE() -> 0 | M9: =FALSE() -> 0 | N9: =TRUE() -> 1 | O9: =TRUE() -> 1 | P9: 2
A10: 109 | B10: Test schedule 109 | C10: Pareto test | D10: 1 | E10: 9 | F10: 3 | G10: 9 | H10: 7 | I10: 0.28042131 | J10: 0.52459601 | K10: 0.6779273 | L10: =FALSE() -> 0 | M10: =FALSE() -> 0 | N10: =TRUE() -> 1 | O10: =TRUE() -> 1 | P10: 2
A11: 109 | B11: Test schedule 109 | C11: Pareto test | D11: 1 | E11: 10 | F11: 3 | G11: 10 | H11: 7 | I11: 0.28042131 | J11: 0.52459601 | K11: 0.6779273 | L11: =FALSE() -> 0 | M11: =FALSE() -> 0 | N11: =TRUE() -> 1 | O11: =TRUE() -> 1 | P11: 2
A12: 109 | B12: Test schedule 109 | C12: Pareto test | D12: 2 | E12: 1 | F12: 3 | G12: 9 | H12: 7 | I12: 0.28042131 | J12: 0.52459601 | K12: 0.6779273 | L12: =FALSE() -> 0 | M12: =FALSE() -> 0 | N12: =TRUE() -> 1 | O12: =TRUE() -> 1 | P12: 2
A13: 109 | B13: Test schedule 109 | C13: Pareto test | D13: 2 | E13: 2 | F13: 3 | G13: 10 | H13: 6 | I13: 0.28042131 | J13: 0.52459601 | K13: 0.6779273 | L13: =FALSE() -> 0 | M13: =FALSE() -> 0 | N13: =TRUE() -> 1 | O13: =TRUE() -> 1 | P13: 2
... A81: 600 | B81: Test schedule 600 | C81: Pareto test | D81: 2 | E81: 10 | F81: 5 | G81: 3 | H81: 6 | I81: 0.48900137 | J81: 0.46586768 | K81: 0.61812688 | L81: =FALSE() -> 0 | M81: =FALSE() -> 0 | N81: =TRUE() -> 1 | O81: =TRUE() -> 1 | P81: 2
A82: 682 | B82: Chef schedule | C82: Chef | D82: 1 | E82: 1 | F82: 5 | G82: 3 | H82: 7 | I82: 0.38230214 | J82: 0.41560091 | K82: 0.80729451 | L82: =TRUE() -> 1 | M82: =FALSE() -> 0 | N82: =TRUE() -> 1 | O82: =FALSE() -> 0 | P82: 2
A83: 682 | B83: Chef schedule | C83: Chef | D83: 1 | E83: 2 | F83: 2 | G83: 2 | H83: 7 | I83: 0.38230214 | J83: 0.41560091 | K83: 0.80729451 | L83: =TRUE() -> 1 | M83: =FALSE() -> 0 | N83: =TRUE() -> 1 | O83: =FALSE() -> 0 | P83: 2
A84: 682 | B84: Chef schedule | C84: Chef | D84: 1 | E84: 3 | F84: 4 | G84: 3 | H84: 9 | I84: 0.38230214 | J84: 0.41560091 | K84: 0.80729451 | L84: =TRUE() -> 1 | M84: =FALSE() -> 0 | N84: =TRUE() -> 1 | O84: =FALSE() -> 0 | P84: 2
A85: 682 | B85: Chef schedule | C85: Chef | D85: 1 | E85: 4 | F85: 5 | G85: 4 | H85: 7 | I85: 0.38230214 | J85: 0.41560091 | K85: 0.80729451 | L85: =TRUE() -> 1 | M85: =FALSE() -> 0 | N85: =TRUE() -> 1 | O85: =FALSE() -> 0 | P85: 2
A86: 682 | B86: Chef schedule | C86: Chef | D86: 1 | E86: 5 | F86: 1 | G86: 3 | H86: 7 | I86: 0.38230214 | J86: 0.41560091 | K86: 0.80729451 | L86: =TRUE() -> 1 | M86: =FALSE() -> 0 | N86: =TRUE() -> 1 | O86: =FALSE() -> 0 | P86: 2
A87: 682 | B87: Chef schedule | C87: Chef | D87: 1 | E87: 6 | F87: 4 | G87: 3 | H87: 7 | I87: 0.38230214 | J87: 0.41560091 | K87: 0.80729451 | L87: =TRUE() -> 1 | M87: =FALSE() -> 0 | N87: =TRUE() -> 1 | O87: =FALSE() -> 0 | P87: 2
A88: 682 | B88: Chef schedule | C88: Chef | D88: 1 | E88: 7 | F88: 4 | G88: 3 | H88: 8 | I88: 0.38230214 | J88: 0.41560091 | K88: 0.80729451 | L88: =TRUE() -> 1 | M88: =FALSE() -> 0 | N88: =TRUE() -> 1 | O88: =FALSE() -> 0 | P88: 2
A89: 682 | B89: Chef schedule | C89: Chef | D89: 1 | E89: 8 | F89: 5 | G89: 3 | H89: 6 | I89: 0.38230214 | J89: 0.41560091 | K89: 0.80729451 | L89: =TRUE() -> 1 | M89: =FALSE() -> 0 | N89: =TRUE() -> 1 | O89: =FALSE() -> 0 | P89: 2
A90: 682 | B90: Chef schedule | C90: Chef | D90: 1 | E90: 9 | F90: 3 | G90: 2 | H90: 5 | I90: 0.38230214 | J90: 0.41560091 | K90: 0.80729451 | L90: =TRUE() -> 1 | M90: =FALSE() -> 0 | N90: =TRUE() -> 1 | O90: =FALSE() -> 0 | P90: 2
A91: 682 | B91: Chef schedule | C91: Chef | D91: 1 | E91: 10 | F91: 4 | G91: 6 | H91: 6 | I91: 0.38230214 | J91: 0.41560091 | K91: 0.80729451 | L91: =TRUE() -> 1 | M91: =FALSE() -> 0 | N91: =TRUE() -> 1 | O91: =FALSE() -> 0 | P91: 2
A92: 682 | B92: Chef schedule | C92: Chef | D92: 2 | E92: 1 | F92: 5 | G92: 5 | H92: 7 | I92: 0.38230214 | J92: 0.41560091 | K92: 0.80729451 | L92: =TRUE() -> 1 | M92: =FALSE() -> 0 | N92: =TRUE() -> 1 | O92: =FALSE() -> 0 | P92: 2
A93: 682 | B93: Chef schedule | C93: Chef | D93: 2 | E93: 2 | F93: 3 | G93: 4 | H93: 8 | I93: 0.38230214 | J93: 0.41560091 | K93: 0.80729451 | L93: =TRUE() -> 1 | M93: =FALSE() -> 0 | N93: =TRUE() -> 1 | O93: =FALSE() -> 0 | P93: 2
... A111: 682 | B111: Chef schedule | C111: Chef | D111: 3 | E111: 10 | F111: 2 | G111: 2 | H111: 8 | I111: 0.38230214 | J111: 0.41560091 | K111: 0.80729451 | L111: =TRUE() -> 1 | M111: =FALSE() -> 0 | N111: =TRUE() -> 1 | O111: =FALSE() -> 0 | P111: 2
A112: 851 | B112: Test schedule 851 | C112: Pareto test | D112: 1 | E112: 1 | F112: 7 | G112: 5 | H112: 7 | I112: 0.70456418 | J112: 0.36732626 | K112: 0.65251452 | L112: =FALSE() -> 0 | M112: =FALSE() -> 0 | N112: =TRUE() -> 1 | O112: =TRUE() -> 1 | P112: 0
A113: 851 | B113: Test schedule 851 | C113: Pareto test | D113: 1 | E113: 2 | F113: 7 | G113: 8 | H113: 6 | I113: 0.70456418 | J113: 0.36732626 | K113: 0.65251452 | L113: =FALSE() -> 0 | M113: =FALSE() -> 0 | N113: =TRUE() -> 1 | O113: =TRUE() -> 1 | P113: 0
A114: 851 | B114: Test schedule 851 | C114: Pareto test | D114: 1 | E114: 3 | F114: 9 | G114: 9 | H114: 8 | I114: 0.70456418 | J114: 0.36732626 | K114: 0.65251452 | L114: =FALSE() -> 0 | M114: =FALSE() -> 0 | N114: =TRUE() -> 1 | O114: =TRUE() -> 1 | P114: 0
A115: 851 | B115: Test schedule 851 | C115: Pareto test | D115: 1 | E115: 4 | F115: 9 | G115: 9 | H115: 9 | I115: 0.70456418 | J115: 0.36732626 | K115: 0.65251452 | L115: =FALSE() -> 0 | M115: =FALSE() -> 0 | N115: =TRUE() -> 1 | O115: =TRUE() -> 1 | P115: 0
A116: 851 | B116: Test schedule 851 | C116: Pareto test | D116: 1 | E116: 5 | F116: 6 | G116: 8 | H116: 7 | I116: 0.70456418 | J116: 0.36732626 | K116: 0.65251452 | L116: =FALSE() -> 0 | M116: =FALSE() -> 0 | N116: =TRUE() -> 1 | O116: =TRUE() -> 1 | P116: 0
A117: 851 | B117: Test schedule 851 | C117: Pareto test | D117: 1 | E117: 6 | F117: 6 | G117: 8 | H117: 7 | I117: 0.70456418 | J117: 0.36732626 | K117: 0.65251452 | L117: =FALSE() -> 0 | M117: =FALSE() -> 0 | N117: =TRUE() -> 1 | O117: =TRUE() -> 1 | P117: 0
